<?xml version="1.0" ?>
<!-- =================================================================================== -->
<!-- |    This document was autogenerated by xacro from mCorin_model.urdf.xacro        | -->
<!-- |    EDITING THIS FILE BY HAND IS NOT RECOMMENDED                                 | -->
<!-- =================================================================================== -->
<robot name="corin" xmlns:xacro="http://www.ros.org/wiki/xacro">
  <!-- 2.62 -->
  <!-- Rectangular box: m*(a^2 + b^2)/12 -->
  <material name="black">
    <color rgba="0.0 0.0 0.0 1.0"/>
  </material>
  <material name="blue">
    <color rgba="0.0 0.0 0.8 1.0"/>
  </material>
  <material name="brown">
    <color rgba="0.870588235294 0.811764705882 0.764705882353 1.0"/>
  </material>
  <material name="colli">
    <color rgba="1.0 0.423529411765 0.0392156862745 0.7"/>
  </material>
  <material name="green">
    <color rgba="0.0 0.8 0.0 1.0"/>
  </material>
  <material name="grey">
    <color rgba="0.2 0.2 0.2 1.0"/>
  </material>
  <material name="grey1">
    <color rgba="0.878431372549 0.878431372549 0.878431372549 1.0"/>
  </material>
  <material name="orange">
    <color rgba="1.0 0.423529411765 0.0392156862745 1.0"/>
  </material>
  <material name="red">
    <color rgba="0.8 0.0 0.0 1.0"/>
  </material>
  <material name="transparent">
    <color rgba="0 0 0 0"/>
  </material>
  <material name="turquoise">
    <color rgba="0 0.807843137255 0.819607843137 1.0"/>
  </material>
  <material name="white">
    <color rgba="1.0 1.0 1.0 1.0"/>
  </material>
  <material name="yellow">
    <color rgba="1 1 0 1"/>
  </material>
  <!-- ================================ Trunk ================================ -->
  <!-- #############  Laser Sensor  ############# -->
  <!-- Noise parameters based on published spec for Hokuyo laser achieving "+-30mm" accuracy at range < 10m. -->
  <!-- A mean of 0.0m and stddev of 0.01m will put 99.7% of samples within 0.03m of the true reading. -->
  <gazebo>
    <plugin filename="libgazebo_ros_control.so" name="gazebo_ros_control">
      <robotNamespace>/corin</robotNamespace>
    </plugin>
    <plugin filename="libgazebo_ros_p3d.so" name="gazebo_ros_p3d">
      <robotNamespace>/corin</robotNamespace>
      <bodyName>trunk</bodyName>
      <topicName>ground_truth</topicName>
      <frameName>world</frameName>
      <xyzOffsets>0 0 0</xyzOffsets>
      <rpyOffsets>0 0 0</rpyOffsets>
      <gaussianNoise>0</gaussianNoise>
      <alwaysOn>true</alwaysOn>
      <updateRate>250.0</updateRate>
    </plugin>
  </gazebo>
  <!-- Now we can start using the macros included above to define the mcorin -->
  <!-- The first use of a macro. This one was defined in trunk.urdf.xacro above.
A macro like this will expand to a set of link and joint definitions, and to additional
Gazebo-related extensions (sensor plugins, etc). The macro takes an argument, name,
that equals "base", and uses it to generate names for its component links and joints
(e.g., base_link). The included origin block is also an argument to the macro. By convention,
the origin block defines where the component is w.r.t its parent (in this case the parent
is the world frame). For more, see http://www.ros.org/wiki/xacro -->
  <!-- Floating-base Joint -->
  <joint name="floating_base" type="fixed">
    <axis xyz="0 0 1"/>
    <!-- origin remains zero as body_dummy same dimensions as body -->
    <origin rpy="0 0 0" xyz="0.0 0.0 0.0"/>
    <parent link="base_link"/>
    <child link="trunk"/>
  </joint>
  <!-- Floating Link  -->
  <link name="base_link">
    <visual>
      <geometry>
        <cylinder length="0.01" radius="0.01"/>
      </geometry>
    </visual>
  </link>
  <!-- Trunk link -->
  <link name="trunk">
    <inertial>
      <origin xyz="0.0 0.0 0.0"/>
      <mass value="1.5"/>
      <inertia ixx="0.0030125" ixy="0.0" ixz="0.0" iyy="0.0155125" iyz="0.0" izz="0.018125"/>
    </inertial>
    <visual>
      <geometry>
        <box size="0.35 0.15 0.04"/>
      </geometry>
      <material name="orange"/>
    </visual>
    <collision>
      <geometry>
        <box size="0.35 0.15 0.04"/>
      </geometry>
      <material name="colli"/>
    </collision>
  </link>
  <gazebo reference="trunk">
    <mu1>1.5</mu1>
    <mu2>1.5</mu2>
    <material>Gazebo/DarkGrey</material>
  </gazebo>
  <!-- Joints -->
  <!-- Coxa joint -->
  <joint name="lf_q1_joint" type="revolute">
    <origin rpy="0 0 1.57079632679" xyz="0.175 0.075 0"/>
    <parent link="trunk"/>
    <child link="lf_hipassembly"/>
    <axis xyz="0 0 1"/>
    <limit effort="2.85" lower="-1.6" upper="1.6" velocity="5.23"/>
    <dynamics damping="0.15" friction="0"/>
    <!-- <safety_controller k_position="100" k_velocity="100"
							   soft_lower_limit="${-7*PI/18}" soft_upper_limit="${5*PI/36}" /> -->
  </joint>
  <!-- Upper leg joint -->
  <joint name="lf_q2_joint" type="revolute">
    <origin rpy="1.57079632679 0 0" xyz="0.077 0 0"/>
    <parent link="lf_hipassembly"/>
    <child link="lf_upperleg"/>
    <axis xyz="0 0 1"/>
    <limit effort="2.85" lower="-2.36" upper="2.36" velocity="5.23"/>
    <dynamics damping="0.15" friction="0"/>
    <!-- <safety_controller k_position="100" k_velocity="100"
							   soft_lower_limit="${-(1+reflect_front)*5*PI/36-(1-reflect_front)*7*PI/36}"
							   soft_upper_limit="${(1-reflect_front)*5*PI/36+(1+reflect_front)*7*PI/36}" /> -->
  </joint>
  <!-- Lower leg joint -->
  <joint name="lf_q3_joint" type="revolute">
    <origin rpy="0 0 0" xyz="0.15 0 0"/>
    <parent link="lf_upperleg"/>
    <child link="lf_lowerleg"/>
    <axis xyz="0 0 1"/>
    <limit effort="2.85" lower="-3.1" upper="3.1" velocity="5.23"/>
    <dynamics damping="0.15" friction="0"/>
    <!-- <safety_controller k_position="100" k_velocity="100"
							   soft_lower_limit="${-(1+reflect_front)*7*PI/18+(1-reflect_front)*PI/18}"
							   soft_upper_limit="${(1-reflect_front)*7*PI/18-(1+reflect_front)*PI/18}" /> -->
  </joint>
  <!-- Foot joint -->
  <joint name="lf_foot_joint" type="fixed">
    <origin rpy="0 0 0" xyz="0.16 0 0"/>
    <parent link="lf_lowerleg"/>
    <child link="lf_foot"/>
  </joint>
  <!-- Links -->
  <!-- Hip assembly link -->
  <link name="lf_hipassembly">
    <visual>
      <origin rpy="0 0 0" xyz="0 0 0"/>
      <geometry>
        <mesh filename="package://mcorin_description/meshes/Coxa.STL" scale="1 1 1"/>
      </geometry>
      <material name="green"/>
    </visual>
    <collision>
      <origin rpy="0 0 0" xyz="0.05945 0 0"/>
      <geometry>
        <box size="0.0611 0.046 0.0528"/>
      </geometry>
      <material name="orange"/>
    </collision>
    <inertial>
      <origin xyz="0.058 0 0"/>
      <mass value="0.175"/>
      <inertia ixx="3.2e-05" ixy="0.0" ixz="0.0" iyy="5.6e-05" iyz="0.0" izz="4e-05"/>
    </inertial>
  </link>
  <!-- Upper leg link -->
  <link name="lf_upperleg">
    <visual>
      <geometry>
        <mesh filename="package://mcorin_description/meshes/Femur.STL" scale="1 1 1"/>
      </geometry>
      <origin rpy="1.57079632679 0 0" xyz="0 0 0"/>
      <material name="blue"/>
    </visual>
    <collision>
      <geometry>
        <box size="0.12 0.04 0.04"/>
      </geometry>
      <origin rpy="0 0 0" xyz="0.1 0 0"/>
      <material name="colli"/>
    </collision>
    <inertial>
      <mass value="0.1554"/>
      <inertia ixx="1.9e-05" ixy="0" ixz="0" iyy="6.8e-05" iyz="0" izz="7.9e-05"/>
      <origin xyz="0.1213 0 0"/>
    </inertial>
  </link>
  <!-- Lower leg link -->
  <link name="lf_lowerleg">
    <visual>
      <geometry>
        <mesh filename="package://mcorin_description/meshes/Tibia.STL" scale="1 1 1"/>
      </geometry>
      <origin rpy="1.57079632679 0 0" xyz="0 0 0"/>
      <material name="yellow"/>
    </visual>
    <collision>
      <geometry>
        <box size="0.12 0.025 0.04"/>
      </geometry>
      <origin rpy="0 0 0" xyz="0.085 0 0"/>
      <material name="colli"/>
    </collision>
    <inertial>
      <mass value="0.0537"/>
      <inertia ixx="1.6e-05" ixy="0" ixz="0" iyy="0.000119" iyz="0" izz="0.00013"/>
      <origin xyz="0.0958 0 0"/>
    </inertial>
  </link>
  <!-- Foot link -->
  <link name="lf_foot">
    <visual>
      <geometry>
        <sphere radius="0.008"/>
      </geometry>
      <origin rpy="0 0 0" xyz="0 0 0"/>
      <material name="blue"/>
    </visual>
    <collision>
      <geometry>
        <sphere radius="0.008"/>
      </geometry>
      <origin rpy="0 0 0" xyz="0 0 0"/>
      <material name="colli"/>
    </collision>
    <inertial>
      <mass value="0.005"/>
      <inertia ixx="5e-05" ixy="0" ixz="0" iyy="5e-05" iyz="0" izz="5e-05"/>
      <origin xyz="0 0 0"/>
    </inertial>
  </link>
  <!-- Hip assembly -->
  <transmission name="lf_q1_trans">
    <type>transmission_interface/SimpleTransmission</type>
    <joint name="lf_q1_joint">
      <hardwareInterface>EffortJointInterface</hardwareInterface>
    </joint>
    <actuator name="lf_q1_motor">
      <hardwareInterface>EffortJointInterface</hardwareInterface>
      <mechanicalReduction>200</mechanicalReduction>
    </actuator>
  </transmission>
  <!-- Upper leg -->
  <transmission name="lf_q2_trans">
    <type>transmission_interface/SimpleTransmission</type>
    <joint name="lf_q2_joint">
      <hardwareInterface>EffortJointInterface</hardwareInterface>
    </joint>
    <actuator name="lf_q2_motor">
      <hardwareInterface>EffortJointInterface</hardwareInterface>
      <mechanicalReduction>200</mechanicalReduction>
    </actuator>
  </transmission>
  <!-- Lower leg -->
  <transmission name="lf_q3_trans">
    <type>transmission_interface/SimpleTransmission</type>
    <joint name="lf_q3_joint">
      <hardwareInterface>EffortJointInterface</hardwareInterface>
    </joint>
    <actuator name="lf_q3_motor">
      <hardwareInterface>EffortJointInterface</hardwareInterface>
      <mechanicalReduction>200</mechanicalReduction>
    </actuator>
  </transmission>
  <gazebo reference="lf_q1_joint">
    <provideFeedback>true</provideFeedback>
  </gazebo>
  <gazebo>
    <plugin filename="libgazebo_ros_ft_sensor.so" name="lf_q1_sensor">
      <robotNamespace>/corin/internal_wrench/</robotNamespace>
      <updateRate>100.0</updateRate>
      <topicName>lf_q1_joint</topicName>
      <jointName>lf_q1_joint</jointName>
    </plugin>
  </gazebo>
  <gazebo reference="lf_q2_joint">
    <provideFeedback>true</provideFeedback>
  </gazebo>
  <gazebo>
    <plugin filename="libgazebo_ros_ft_sensor.so" name="lf_q2_sensor">
      <robotNamespace>/corin/internal_wrench/</robotNamespace>
      <updateRate>100.0</updateRate>
      <topicName>lf_q2_joint</topicName>
      <jointName>lf_q2_joint</jointName>
    </plugin>
  </gazebo>
  <gazebo reference="lf_q3_joint">
    <provideFeedback>true</provideFeedback>
  </gazebo>
  <gazebo>
    <plugin filename="libgazebo_ros_ft_sensor.so" name="lf_q3_sensor">
      <robotNamespace>/corin/internal_wrench/</robotNamespace>
      <updateRate>100.0</updateRate>
      <topicName>lf_q3_joint</topicName>
      <jointName>lf_q3_joint</jointName>
    </plugin>
  </gazebo>
  <gazebo reference="lf_hipassembly">
    <kp>1000000.0</kp>
    <kd>100.0</kd>
    <mu1>1.5</mu1>
    <mu2>1.5</mu2>
    <!-- <fdir1>1 0 0</fdir1> -->
    <maxVel>0.001</maxVel>
    <minDepth>0.00</minDepth>
    <material>Gazebo/White</material>
  </gazebo>
  <gazebo reference="lf_upperleg">
    <kp>1000000.0</kp>
    <kd>100.0</kd>
    <mu1>1.5</mu1>
    <mu2>1.5</mu2>
    <!-- <fdir1>1 0 0</fdir1> -->
    <maxVel>0.001</maxVel>
    <minDepth>0.00</minDepth>
    <material>Gazebo/DarkGrey</material>
  </gazebo>
  <gazebo reference="lf_lowerleg">
    <kp>1000000.0</kp>
    <kd>100.0</kd>
    <mu1>1.5</mu1>
    <mu2>1.5</mu2>
    <!-- <fdir1>1 0 0</fdir1> -->
    <maxVel>0.001</maxVel>
    <minDepth>0.00</minDepth>
    <material>Gazebo/White</material>
  </gazebo>
  <gazebo reference="lf_foot">
    <kp>1000000.0</kp>
    <kd>100.0</kd>
    <mu1>1.5</mu1>
    <mu2>1.5</mu2>
    <!-- <fdir1>1 0 0</fdir1> -->
    <maxVel>0.001</maxVel>
    <minDepth>0.00</minDepth>
    <material>Gazebo/Black</material>
  </gazebo>
  <gazebo reference="lf_foot">
    <!-- contact sensor -->
    <sensor name="foot_contact" type="contact">
      <update_rate>100.0</update_rate>
      <always_on>1</always_on>
      <contact>
        <collision>lf_lowerleg_fixed_joint_lump__lf_foot_collision_1</collision>
        <topic>/lf_foot_contact</topic>
      </contact>
      <plugin filename="libgazebo_ros_bumper.so" name="fixed_jaw_bumper">
        <bumperTopicName>/corin/foot_wrench/lf</bumperTopicName>
        <frameName>lf_foot</frameName>
      </plugin>
    </sensor>
  </gazebo>
  <!-- Joints -->
  <!-- Coxa joint -->
  <joint name="lm_q1_joint" type="revolute">
    <origin rpy="0 0 1.57079632679" xyz="0 0.075 0"/>
    <parent link="trunk"/>
    <child link="lm_hipassembly"/>
    <axis xyz="0 0 1"/>
    <limit effort="2.85" lower="-1.6" upper="1.6" velocity="5.23"/>
    <dynamics damping="0.15" friction="0"/>
    <!-- <safety_controller k_position="100" k_velocity="100"
							   soft_lower_limit="${-7*PI/18}" soft_upper_limit="${5*PI/36}" /> -->
  </joint>
  <!-- Upper leg joint -->
  <joint name="lm_q2_joint" type="revolute">
    <origin rpy="1.57079632679 0 0" xyz="0.077 0 0"/>
    <parent link="lm_hipassembly"/>
    <child link="lm_upperleg"/>
    <axis xyz="0 0 1"/>
    <limit effort="2.85" lower="-2.36" upper="2.36" velocity="5.23"/>
    <dynamics damping="0.15" friction="0"/>
    <!-- <safety_controller k_position="100" k_velocity="100"
							   soft_lower_limit="${-(1+reflect_front)*5*PI/36-(1-reflect_front)*7*PI/36}"
							   soft_upper_limit="${(1-reflect_front)*5*PI/36+(1+reflect_front)*7*PI/36}" /> -->
  </joint>
  <!-- Lower leg joint -->
  <joint name="lm_q3_joint" type="revolute">
    <origin rpy="0 0 0" xyz="0.15 0 0"/>
    <parent link="lm_upperleg"/>
    <child link="lm_lowerleg"/>
    <axis xyz="0 0 1"/>
    <limit effort="2.85" lower="-3.1" upper="3.1" velocity="5.23"/>
    <dynamics damping="0.15" friction="0"/>
    <!-- <safety_controller k_position="100" k_velocity="100"
							   soft_lower_limit="${-(1+reflect_front)*7*PI/18+(1-reflect_front)*PI/18}"
							   soft_upper_limit="${(1-reflect_front)*7*PI/18-(1+reflect_front)*PI/18}" /> -->
  </joint>
  <!-- Foot joint -->
  <joint name="lm_foot_joint" type="fixed">
    <origin rpy="0 0 0" xyz="0.16 0 0"/>
    <parent link="lm_lowerleg"/>
    <child link="lm_foot"/>
  </joint>
  <!-- Links -->
  <!-- Hip assembly link -->
  <link name="lm_hipassembly">
    <visual>
      <origin rpy="0 0 0" xyz="0 0 0"/>
      <geometry>
        <mesh filename="package://mcorin_description/meshes/Coxa.STL" scale="1 1 1"/>
      </geometry>
      <material name="green"/>
    </visual>
    <collision>
      <origin rpy="0 0 0" xyz="0.05945 0 0"/>
      <geometry>
        <box size="0.0611 0.046 0.0528"/>
      </geometry>
      <material name="orange"/>
    </collision>
    <inertial>
      <origin xyz="0.058 0 0"/>
      <mass value="0.175"/>
      <inertia ixx="3.2e-05" ixy="0.0" ixz="0.0" iyy="5.6e-05" iyz="0.0" izz="4e-05"/>
    </inertial>
  </link>
  <!-- Upper leg link -->
  <link name="lm_upperleg">
    <visual>
      <geometry>
        <mesh filename="package://mcorin_description/meshes/Femur.STL" scale="1 1 1"/>
      </geometry>
      <origin rpy="1.57079632679 0 0" xyz="0 0 0"/>
      <material name="blue"/>
    </visual>
    <collision>
      <geometry>
        <box size="0.12 0.04 0.04"/>
      </geometry>
      <origin rpy="0 0 0" xyz="0.1 0 0"/>
      <material name="colli"/>
    </collision>
    <inertial>
      <mass value="0.1554"/>
      <inertia ixx="1.9e-05" ixy="0" ixz="0" iyy="6.8e-05" iyz="0" izz="7.9e-05"/>
      <origin xyz="0.1213 0 0"/>
    </inertial>
  </link>
  <!-- Lower leg link -->
  <link name="lm_lowerleg">
    <visual>
      <geometry>
        <mesh filename="package://mcorin_description/meshes/Tibia.STL" scale="1 1 1"/>
      </geometry>
      <origin rpy="1.57079632679 0 0" xyz="0 0 0"/>
      <material name="yellow"/>
    </visual>
    <collision>
      <geometry>
        <box size="0.12 0.025 0.04"/>
      </geometry>
      <origin rpy="0 0 0" xyz="0.085 0 0"/>
      <material name="colli"/>
    </collision>
    <inertial>
      <mass value="0.0537"/>
      <inertia ixx="1.6e-05" ixy="0" ixz="0" iyy="0.000119" iyz="0" izz="0.00013"/>
      <origin xyz="0.0958 0 0"/>
    </inertial>
  </link>
  <!-- Foot link -->
  <link name="lm_foot">
    <visual>
      <geometry>
        <sphere radius="0.008"/>
      </geometry>
      <origin rpy="0 0 0" xyz="0 0 0"/>
      <material name="blue"/>
    </visual>
    <collision>
      <geometry>
        <sphere radius="0.008"/>
      </geometry>
      <origin rpy="0 0 0" xyz="0 0 0"/>
      <material name="colli"/>
    </collision>
    <inertial>
      <mass value="0.005"/>
      <inertia ixx="5e-05" ixy="0" ixz="0" iyy="5e-05" iyz="0" izz="5e-05"/>
      <origin xyz="0 0 0"/>
    </inertial>
  </link>
  <!-- Hip assembly -->
  <transmission name="lm_q1_trans">
    <type>transmission_interface/SimpleTransmission</type>
    <joint name="lm_q1_joint">
      <hardwareInterface>EffortJointInterface</hardwareInterface>
    </joint>
    <actuator name="lm_q1_motor">
      <hardwareInterface>EffortJointInterface</hardwareInterface>
      <mechanicalReduction>200</mechanicalReduction>
    </actuator>
  </transmission>
  <!-- Upper leg -->
  <transmission name="lm_q2_trans">
    <type>transmission_interface/SimpleTransmission</type>
    <joint name="lm_q2_joint">
      <hardwareInterface>EffortJointInterface</hardwareInterface>
    </joint>
    <actuator name="lm_q2_motor">
      <hardwareInterface>EffortJointInterface</hardwareInterface>
      <mechanicalReduction>200</mechanicalReduction>
    </actuator>
  </transmission>
  <!-- Lower leg -->
  <transmission name="lm_q3_trans">
    <type>transmission_interface/SimpleTransmission</type>
    <joint name="lm_q3_joint">
      <hardwareInterface>EffortJointInterface</hardwareInterface>
    </joint>
    <actuator name="lm_q3_motor">
      <hardwareInterface>EffortJointInterface</hardwareInterface>
      <mechanicalReduction>200</mechanicalReduction>
    </actuator>
  </transmission>
  <gazebo reference="lm_q1_joint">
    <provideFeedback>true</provideFeedback>
  </gazebo>
  <gazebo reference="lm_q2_joint">
    <provideFeedback>true</provideFeedback>
  </gazebo>
  <gazebo reference="lm_q3_joint">
    <provideFeedback>true</provideFeedback>
  </gazebo>
  <gazebo reference="lm_hipassembly">
    <kp>1000000.0</kp>
    <kd>100.0</kd>
    <mu1>1.5</mu1>
    <mu2>1.5</mu2>
    <!-- <fdir1>1 0 0</fdir1> -->
    <maxVel>0.001</maxVel>
    <minDepth>0.00</minDepth>
    <material>Gazebo/White</material>
  </gazebo>
  <gazebo reference="lm_upperleg">
    <kp>1000000.0</kp>
    <kd>100.0</kd>
    <mu1>1.5</mu1>
    <mu2>1.5</mu2>
    <!-- <fdir1>1 0 0</fdir1> -->
    <maxVel>0.001</maxVel>
    <minDepth>0.00</minDepth>
    <material>Gazebo/DarkGrey</material>
  </gazebo>
  <gazebo reference="lm_lowerleg">
    <kp>1000000.0</kp>
    <kd>100.0</kd>
    <mu1>1.5</mu1>
    <mu2>1.5</mu2>
    <!-- <fdir1>1 0 0</fdir1> -->
    <maxVel>0.001</maxVel>
    <minDepth>0.00</minDepth>
    <material>Gazebo/White</material>
  </gazebo>
  <gazebo reference="lm_foot">
    <kp>1000000.0</kp>
    <kd>100.0</kd>
    <mu1>1.5</mu1>
    <mu2>1.5</mu2>
    <!-- <fdir1>1 0 0</fdir1> -->
    <maxVel>0.001</maxVel>
    <minDepth>0.00</minDepth>
    <material>Gazebo/Black</material>
  </gazebo>
  <gazebo reference="lm_foot">
    <!-- contact sensor -->
    <sensor name="foot_contact" type="contact">
      <update_rate>100.0</update_rate>
      <always_on>1</always_on>
      <contact>
        <collision>lm_lowerleg_fixed_joint_lump__lm_foot_collision_1</collision>
        <topic>/lm_foot_contact</topic>
      </contact>
      <plugin filename="libgazebo_ros_bumper.so" name="fixed_jaw_bumper">
        <bumperTopicName>/corin/foot_wrench/lm</bumperTopicName>
        <frameName>lm_foot</frameName>
      </plugin>
    </sensor>
  </gazebo>
  <!-- Joints -->
  <!-- Coxa joint -->
  <joint name="lr_q1_joint" type="revolute">
    <origin rpy="0 0 1.57079632679" xyz="-0.175 0.075 0"/>
    <parent link="trunk"/>
    <child link="lr_hipassembly"/>
    <axis xyz="0 0 1"/>
    <limit effort="2.85" lower="-1.6" upper="1.6" velocity="5.23"/>
    <dynamics damping="0.15" friction="0"/>
    <!-- <safety_controller k_position="100" k_velocity="100"
							   soft_lower_limit="${-7*PI/18}" soft_upper_limit="${5*PI/36}" /> -->
  </joint>
  <!-- Upper leg joint -->
  <joint name="lr_q2_joint" type="revolute">
    <origin rpy="1.57079632679 0 0" xyz="0.077 0 0"/>
    <parent link="lr_hipassembly"/>
    <child link="lr_upperleg"/>
    <axis xyz="0 0 1"/>
    <limit effort="2.85" lower="-2.36" upper="2.36" velocity="5.23"/>
    <dynamics damping="0.15" friction="0"/>
    <!-- <safety_controller k_position="100" k_velocity="100"
							   soft_lower_limit="${-(1+reflect_front)*5*PI/36-(1-reflect_front)*7*PI/36}"
							   soft_upper_limit="${(1-reflect_front)*5*PI/36+(1+reflect_front)*7*PI/36}" /> -->
  </joint>
  <!-- Lower leg joint -->
  <joint name="lr_q3_joint" type="revolute">
    <origin rpy="0 0 0" xyz="0.15 0 0"/>
    <parent link="lr_upperleg"/>
    <child link="lr_lowerleg"/>
    <axis xyz="0 0 1"/>
    <limit effort="2.85" lower="-3.1" upper="3.1" velocity="5.23"/>
    <dynamics damping="0.15" friction="0"/>
    <!-- <safety_controller k_position="100" k_velocity="100"
							   soft_lower_limit="${-(1+reflect_front)*7*PI/18+(1-reflect_front)*PI/18}"
							   soft_upper_limit="${(1-reflect_front)*7*PI/18-(1+reflect_front)*PI/18}" /> -->
  </joint>
  <!-- Foot joint -->
  <joint name="lr_foot_joint" type="fixed">
    <origin rpy="0 0 0" xyz="0.16 0 0"/>
    <parent link="lr_lowerleg"/>
    <child link="lr_foot"/>
  </joint>
  <!-- Links -->
  <!-- Hip assembly link -->
  <link name="lr_hipassembly">
    <visual>
      <origin rpy="0 0 0" xyz="0 0 0"/>
      <geometry>
        <mesh filename="package://mcorin_description/meshes/Coxa.STL" scale="1 1 1"/>
      </geometry>
      <material name="green"/>
    </visual>
    <collision>
      <origin rpy="0 0 0" xyz="0.05945 0 0"/>
      <geometry>
        <box size="0.0611 0.046 0.0528"/>
      </geometry>
      <material name="orange"/>
    </collision>
    <inertial>
      <origin xyz="0.058 0 0"/>
      <mass value="0.175"/>
      <inertia ixx="3.2e-05" ixy="0.0" ixz="0.0" iyy="5.6e-05" iyz="0.0" izz="4e-05"/>
    </inertial>
  </link>
  <!-- Upper leg link -->
  <link name="lr_upperleg">
    <visual>
      <geometry>
        <mesh filename="package://mcorin_description/meshes/Femur.STL" scale="1 1 1"/>
      </geometry>
      <origin rpy="1.57079632679 0 0" xyz="0 0 0"/>
      <material name="blue"/>
    </visual>
    <collision>
      <geometry>
        <box size="0.12 0.04 0.04"/>
      </geometry>
      <origin rpy="0 0 0" xyz="0.1 0 0"/>
      <material name="colli"/>
    </collision>
    <inertial>
      <mass value="0.1554"/>
      <inertia ixx="1.9e-05" ixy="0" ixz="0" iyy="6.8e-05" iyz="0" izz="7.9e-05"/>
      <origin xyz="0.1213 0 0"/>
    </inertial>
  </link>
  <!-- Lower leg link -->
  <link name="lr_lowerleg">
    <visual>
      <geometry>
        <mesh filename="package://mcorin_description/meshes/Tibia.STL" scale="1 1 1"/>
      </geometry>
      <origin rpy="1.57079632679 0 0" xyz="0 0 0"/>
      <material name="yellow"/>
    </visual>
    <collision>
      <geometry>
        <box size="0.12 0.025 0.04"/>
      </geometry>
      <origin rpy="0 0 0" xyz="0.085 0 0"/>
      <material name="colli"/>
    </collision>
    <inertial>
      <mass value="0.0537"/>
      <inertia ixx="1.6e-05" ixy="0" ixz="0" iyy="0.000119" iyz="0" izz="0.00013"/>
      <origin xyz="0.0958 0 0"/>
    </inertial>
  </link>
  <!-- Foot link -->
  <link name="lr_foot">
    <visual>
      <geometry>
        <sphere radius="0.008"/>
      </geometry>
      <origin rpy="0 0 0" xyz="0 0 0"/>
      <material name="blue"/>
    </visual>
    <collision>
      <geometry>
        <sphere radius="0.008"/>
      </geometry>
      <origin rpy="0 0 0" xyz="0 0 0"/>
      <material name="colli"/>
    </collision>
    <inertial>
      <mass value="0.005"/>
      <inertia ixx="5e-05" ixy="0" ixz="0" iyy="5e-05" iyz="0" izz="5e-05"/>
      <origin xyz="0 0 0"/>
    </inertial>
  </link>
  <!-- Hip assembly -->
  <transmission name="lr_q1_trans">
    <type>transmission_interface/SimpleTransmission</type>
    <joint name="lr_q1_joint">
      <hardwareInterface>EffortJointInterface</hardwareInterface>
    </joint>
    <actuator name="lr_q1_motor">
      <hardwareInterface>EffortJointInterface</hardwareInterface>
      <mechanicalReduction>200</mechanicalReduction>
    </actuator>
  </transmission>
  <!-- Upper leg -->
  <transmission name="lr_q2_trans">
    <type>transmission_interface/SimpleTransmission</type>
    <joint name="lr_q2_joint">
      <hardwareInterface>EffortJointInterface</hardwareInterface>
    </joint>
    <actuator name="lr_q2_motor">
      <hardwareInterface>EffortJointInterface</hardwareInterface>
      <mechanicalReduction>200</mechanicalReduction>
    </actuator>
  </transmission>
  <!-- Lower leg -->
  <transmission name="lr_q3_trans">
    <type>transmission_interface/SimpleTransmission</type>
    <joint name="lr_q3_joint">
      <hardwareInterface>EffortJointInterface</hardwareInterface>
    </joint>
    <actuator name="lr_q3_motor">
      <hardwareInterface>EffortJointInterface</hardwareInterface>
      <mechanicalReduction>200</mechanicalReduction>
    </actuator>
  </transmission>
  <gazebo reference="lr_q1_joint">
    <provideFeedback>true</provideFeedback>
  </gazebo>
  <gazebo reference="lr_q2_joint">
    <provideFeedback>true</provideFeedback>
  </gazebo>
  <gazebo reference="lr_q3_joint">
    <provideFeedback>true</provideFeedback>
  </gazebo>
  <gazebo reference="lr_hipassembly">
    <kp>1000000.0</kp>
    <kd>100.0</kd>
    <mu1>1.5</mu1>
    <mu2>1.5</mu2>
    <!-- <fdir1>1 0 0</fdir1> -->
    <maxVel>0.001</maxVel>
    <minDepth>0.00</minDepth>
    <material>Gazebo/White</material>
  </gazebo>
  <gazebo reference="lr_upperleg">
    <kp>1000000.0</kp>
    <kd>100.0</kd>
    <mu1>1.5</mu1>
    <mu2>1.5</mu2>
    <!-- <fdir1>1 0 0</fdir1> -->
    <maxVel>0.001</maxVel>
    <minDepth>0.00</minDepth>
    <material>Gazebo/DarkGrey</material>
  </gazebo>
  <gazebo reference="lr_lowerleg">
    <kp>1000000.0</kp>
    <kd>100.0</kd>
    <mu1>1.5</mu1>
    <mu2>1.5</mu2>
    <!-- <fdir1>1 0 0</fdir1> -->
    <maxVel>0.001</maxVel>
    <minDepth>0.00</minDepth>
    <material>Gazebo/White</material>
  </gazebo>
  <gazebo reference="lr_foot">
    <kp>1000000.0</kp>
    <kd>100.0</kd>
    <mu1>1.5</mu1>
    <mu2>1.5</mu2>
    <!-- <fdir1>1 0 0</fdir1> -->
    <maxVel>0.001</maxVel>
    <minDepth>0.00</minDepth>
    <material>Gazebo/Black</material>
  </gazebo>
  <gazebo reference="lr_foot">
    <!-- contact sensor -->
    <sensor name="foot_contact" type="contact">
      <update_rate>100.0</update_rate>
      <always_on>1</always_on>
      <contact>
        <collision>lr_lowerleg_fixed_joint_lump__lr_foot_collision_1</collision>
        <topic>/lr_foot_contact</topic>
      </contact>
      <plugin filename="libgazebo_ros_bumper.so" name="fixed_jaw_bumper">
        <bumperTopicName>/corin/foot_wrench/lr</bumperTopicName>
        <frameName>lr_foot</frameName>
      </plugin>
    </sensor>
  </gazebo>
  <!-- Joints -->
  <!-- Coxa joint -->
  <joint name="rf_q1_joint" type="revolute">
    <origin rpy="0 0 -1.57079632679" xyz="0.175 -0.075 0"/>
    <parent link="trunk"/>
    <child link="rf_hipassembly"/>
    <axis xyz="0 0 1"/>
    <limit effort="2.85" lower="-1.6" upper="1.6" velocity="5.23"/>
    <dynamics damping="0.15" friction="0"/>
    <!-- <safety_controller k_position="100" k_velocity="100"
							   soft_lower_limit="${-7*PI/18}" soft_upper_limit="${5*PI/36}" /> -->
  </joint>
  <!-- Upper leg joint -->
  <joint name="rf_q2_joint" type="revolute">
    <origin rpy="1.57079632679 0 0" xyz="0.077 0 0"/>
    <parent link="rf_hipassembly"/>
    <child link="rf_upperleg"/>
    <axis xyz="0 0 1"/>
    <limit effort="2.85" lower="-2.36" upper="2.36" velocity="5.23"/>
    <dynamics damping="0.15" friction="0"/>
    <!-- <safety_controller k_position="100" k_velocity="100"
							   soft_lower_limit="${-(1+reflect_front)*5*PI/36-(1-reflect_front)*7*PI/36}"
							   soft_upper_limit="${(1-reflect_front)*5*PI/36+(1+reflect_front)*7*PI/36}" /> -->
  </joint>
  <!-- Lower leg joint -->
  <joint name="rf_q3_joint" type="revolute">
    <origin rpy="0 0 0" xyz="0.15 0 0"/>
    <parent link="rf_upperleg"/>
    <child link="rf_lowerleg"/>
    <axis xyz="0 0 1"/>
    <limit effort="2.85" lower="-3.1" upper="3.1" velocity="5.23"/>
    <dynamics damping="0.15" friction="0"/>
    <!-- <safety_controller k_position="100" k_velocity="100"
							   soft_lower_limit="${-(1+reflect_front)*7*PI/18+(1-reflect_front)*PI/18}"
							   soft_upper_limit="${(1-reflect_front)*7*PI/18-(1+reflect_front)*PI/18}" /> -->
  </joint>
  <!-- Foot joint -->
  <joint name="rf_foot_joint" type="fixed">
    <origin rpy="0 0 0" xyz="0.16 0 0"/>
    <parent link="rf_lowerleg"/>
    <child link="rf_foot"/>
  </joint>
  <!-- Links -->
  <!-- Hip assembly link -->
  <link name="rf_hipassembly">
    <visual>
      <origin rpy="0 0 0" xyz="0 0 0"/>
      <geometry>
        <mesh filename="package://mcorin_description/meshes/Coxa.STL" scale="1 1 1"/>
      </geometry>
      <material name="green"/>
    </visual>
    <collision>
      <origin rpy="0 0 0" xyz="0.05945 0 0"/>
      <geometry>
        <box size="0.0611 0.046 0.0528"/>
      </geometry>
      <material name="orange"/>
    </collision>
    <inertial>
      <origin xyz="0.058 0 0"/>
      <mass value="0.175"/>
      <inertia ixx="3.2e-05" ixy="0.0" ixz="0.0" iyy="5.6e-05" iyz="0.0" izz="4e-05"/>
    </inertial>
  </link>
  <!-- Upper leg link -->
  <link name="rf_upperleg">
    <visual>
      <geometry>
        <mesh filename="package://mcorin_description/meshes/Femur.STL" scale="1 1 1"/>
      </geometry>
      <origin rpy="1.57079632679 0 0" xyz="0 0 0"/>
      <material name="blue"/>
    </visual>
    <collision>
      <geometry>
        <box size="0.12 0.04 0.04"/>
      </geometry>
      <origin rpy="0 0 0" xyz="0.1 0 0"/>
      <material name="colli"/>
    </collision>
    <inertial>
      <mass value="0.1554"/>
      <inertia ixx="1.9e-05" ixy="0" ixz="0" iyy="6.8e-05" iyz="0" izz="7.9e-05"/>
      <origin xyz="0.1213 0 0"/>
    </inertial>
  </link>
  <!-- Lower leg link -->
  <link name="rf_lowerleg">
    <visual>
      <geometry>
        <mesh filename="package://mcorin_description/meshes/Tibia.STL" scale="1 1 1"/>
      </geometry>
      <origin rpy="1.57079632679 0 0" xyz="0 0 0"/>
      <material name="yellow"/>
    </visual>
    <collision>
      <geometry>
        <box size="0.12 0.025 0.04"/>
      </geometry>
      <origin rpy="0 0 0" xyz="0.085 0 0"/>
      <material name="colli"/>
    </collision>
    <inertial>
      <mass value="0.0537"/>
      <inertia ixx="1.6e-05" ixy="0" ixz="0" iyy="0.000119" iyz="0" izz="0.00013"/>
      <origin xyz="0.0958 0 0"/>
    </inertial>
  </link>
  <!-- Foot link -->
  <link name="rf_foot">
    <visual>
      <geometry>
        <sphere radius="0.008"/>
      </geometry>
      <origin rpy="0 0 0" xyz="0 0 0"/>
      <material name="blue"/>
    </visual>
    <collision>
      <geometry>
        <sphere radius="0.008"/>
      </geometry>
      <origin rpy="0 0 0" xyz="0 0 0"/>
      <material name="colli"/>
    </collision>
    <inertial>
      <mass value="0.005"/>
      <inertia ixx="5e-05" ixy="0" ixz="0" iyy="5e-05" iyz="0" izz="5e-05"/>
      <origin xyz="0 0 0"/>
    </inertial>
  </link>
  <!-- Hip assembly -->
  <transmission name="rf_q1_trans">
    <type>transmission_interface/SimpleTransmission</type>
    <joint name="rf_q1_joint">
      <hardwareInterface>EffortJointInterface</hardwareInterface>
    </joint>
    <actuator name="rf_q1_motor">
      <hardwareInterface>EffortJointInterface</hardwareInterface>
      <mechanicalReduction>200</mechanicalReduction>
    </actuator>
  </transmission>
  <!-- Upper leg -->
  <transmission name="rf_q2_trans">
    <type>transmission_interface/SimpleTransmission</type>
    <joint name="rf_q2_joint">
      <hardwareInterface>EffortJointInterface</hardwareInterface>
    </joint>
    <actuator name="rf_q2_motor">
      <hardwareInterface>EffortJointInterface</hardwareInterface>
      <mechanicalReduction>200</mechanicalReduction>
    </actuator>
  </transmission>
  <!-- Lower leg -->
  <transmission name="rf_q3_trans">
    <type>transmission_interface/SimpleTransmission</type>
    <joint name="rf_q3_joint">
      <hardwareInterface>EffortJointInterface</hardwareInterface>
    </joint>
    <actuator name="rf_q3_motor">
      <hardwareInterface>EffortJointInterface</hardwareInterface>
      <mechanicalReduction>200</mechanicalReduction>
    </actuator>
  </transmission>
  <gazebo reference="rf_q1_joint">
    <provideFeedback>true</provideFeedback>
  </gazebo>
  <gazebo>
    <plugin filename="libgazebo_ros_ft_sensor.so" name="rf_q1_sensor">
      <robotNamespace>/corin/internal_wrench/</robotNamespace>
      <updateRate>100.0</updateRate>
      <topicName>rf_q1_joint</topicName>
      <jointName>rf_q1_joint</jointName>
    </plugin>
  </gazebo>
  <gazebo reference="rf_q2_joint">
    <provideFeedback>true</provideFeedback>
  </gazebo>
  <gazebo>
    <plugin filename="libgazebo_ros_ft_sensor.so" name="rf_q2_sensor">
      <robotNamespace>/corin/internal_wrench/</robotNamespace>
      <updateRate>100.0</updateRate>
      <topicName>rf_q2_joint</topicName>
      <jointName>rf_q2_joint</jointName>
    </plugin>
  </gazebo>
  <gazebo reference="rf_q3_joint">
    <provideFeedback>true</provideFeedback>
  </gazebo>
  <gazebo>
    <plugin filename="libgazebo_ros_ft_sensor.so" name="rf_q3_sensor">
      <robotNamespace>/corin/internal_wrench/</robotNamespace>
      <updateRate>100.0</updateRate>
      <topicName>rf_q3_joint</topicName>
      <jointName>rf_q3_joint</jointName>
    </plugin>
  </gazebo>
  <gazebo reference="rf_hipassembly">
    <kp>1000000.0</kp>
    <kd>100.0</kd>
    <mu1>1.5</mu1>
    <mu2>1.5</mu2>
    <!-- <fdir1>1 0 0</fdir1> -->
    <maxVel>0.001</maxVel>
    <minDepth>0.00</minDepth>
    <material>Gazebo/White</material>
  </gazebo>
  <gazebo reference="rf_upperleg">
    <kp>1000000.0</kp>
    <kd>100.0</kd>
    <mu1>1.5</mu1>
    <mu2>1.5</mu2>
    <!-- <fdir1>1 0 0</fdir1> -->
    <maxVel>0.001</maxVel>
    <minDepth>0.00</minDepth>
    <material>Gazebo/DarkGrey</material>
  </gazebo>
  <gazebo reference="rf_lowerleg">
    <kp>1000000.0</kp>
    <kd>100.0</kd>
    <mu1>1.5</mu1>
    <mu2>1.5</mu2>
    <!-- <fdir1>1 0 0</fdir1> -->
    <maxVel>0.001</maxVel>
    <minDepth>0.00</minDepth>
    <material>Gazebo/White</material>
  </gazebo>
  <gazebo reference="rf_foot">
    <kp>1000000.0</kp>
    <kd>100.0</kd>
    <mu1>1.5</mu1>
    <mu2>1.5</mu2>
    <!-- <fdir1>1 0 0</fdir1> -->
    <maxVel>0.001</maxVel>
    <minDepth>0.00</minDepth>
    <material>Gazebo/Black</material>
  </gazebo>
  <gazebo reference="rf_foot">
    <!-- contact sensor -->
    <sensor name="foot_contact" type="contact">
      <update_rate>100.0</update_rate>
      <always_on>1</always_on>
      <contact>
        <collision>rf_lowerleg_fixed_joint_lump__rf_foot_collision_1</collision>
        <topic>/rf_foot_contact</topic>
      </contact>
      <plugin filename="libgazebo_ros_bumper.so" name="fixed_jaw_bumper">
        <bumperTopicName>/corin/foot_wrench/rf</bumperTopicName>
        <frameName>rf_foot</frameName>
      </plugin>
    </sensor>
  </gazebo>
  <!-- Joints -->
  <!-- Coxa joint -->
  <joint name="rm_q1_joint" type="revolute">
    <origin rpy="0 0 -1.57079632679" xyz="0 -0.075 0"/>
    <parent link="trunk"/>
    <child link="rm_hipassembly"/>
    <axis xyz="0 0 1"/>
    <limit effort="2.85" lower="-1.6" upper="1.6" velocity="5.23"/>
    <dynamics damping="0.15" friction="0"/>
    <!-- <safety_controller k_position="100" k_velocity="100"
							   soft_lower_limit="${-7*PI/18}" soft_upper_limit="${5*PI/36}" /> -->
  </joint>
  <!-- Upper leg joint -->
  <joint name="rm_q2_joint" type="revolute">
    <origin rpy="1.57079632679 0 0" xyz="0.077 0 0"/>
    <parent link="rm_hipassembly"/>
    <child link="rm_upperleg"/>
    <axis xyz="0 0 1"/>
    <limit effort="2.85" lower="-2.36" upper="2.36" velocity="5.23"/>
    <dynamics damping="0.15" friction="0"/>
    <!-- <safety_controller k_position="100" k_velocity="100"
							   soft_lower_limit="${-(1+reflect_front)*5*PI/36-(1-reflect_front)*7*PI/36}"
							   soft_upper_limit="${(1-reflect_front)*5*PI/36+(1+reflect_front)*7*PI/36}" /> -->
  </joint>
  <!-- Lower leg joint -->
  <joint name="rm_q3_joint" type="revolute">
    <origin rpy="0 0 0" xyz="0.15 0 0"/>
    <parent link="rm_upperleg"/>
    <child link="rm_lowerleg"/>
    <axis xyz="0 0 1"/>
    <limit effort="2.85" lower="-3.1" upper="3.1" velocity="5.23"/>
    <dynamics damping="0.15" friction="0"/>
    <!-- <safety_controller k_position="100" k_velocity="100"
							   soft_lower_limit="${-(1+reflect_front)*7*PI/18+(1-reflect_front)*PI/18}"
							   soft_upper_limit="${(1-reflect_front)*7*PI/18-(1+reflect_front)*PI/18}" /> -->
  </joint>
  <!-- Foot joint -->
  <joint name="rm_foot_joint" type="fixed">
    <origin rpy="0 0 0" xyz="0.16 0 0"/>
    <parent link="rm_lowerleg"/>
    <child link="rm_foot"/>
  </joint>
  <!-- Links -->
  <!-- Hip assembly link -->
  <link name="rm_hipassembly">
    <visual>
      <origin rpy="0 0 0" xyz="0 0 0"/>
      <geometry>
        <mesh filename="package://mcorin_description/meshes/Coxa.STL" scale="1 1 1"/>
      </geometry>
      <material name="green"/>
    </visual>
    <collision>
      <origin rpy="0 0 0" xyz="0.05945 0 0"/>
      <geometry>
        <box size="0.0611 0.046 0.0528"/>
      </geometry>
      <material name="orange"/>
    </collision>
    <inertial>
      <origin xyz="0.058 0 0"/>
      <mass value="0.175"/>
      <inertia ixx="3.2e-05" ixy="0.0" ixz="0.0" iyy="5.6e-05" iyz="0.0" izz="4e-05"/>
    </inertial>
  </link>
  <!-- Upper leg link -->
  <link name="rm_upperleg">
    <visual>
      <geometry>
        <mesh filename="package://mcorin_description/meshes/Femur.STL" scale="1 1 1"/>
      </geometry>
      <origin rpy="1.57079632679 0 0" xyz="0 0 0"/>
      <material name="blue"/>
    </visual>
    <collision>
      <geometry>
        <box size="0.12 0.04 0.04"/>
      </geometry>
      <origin rpy="0 0 0" xyz="0.1 0 0"/>
      <material name="colli"/>
    </collision>
    <inertial>
      <mass value="0.1554"/>
      <inertia ixx="1.9e-05" ixy="0" ixz="0" iyy="6.8e-05" iyz="0" izz="7.9e-05"/>
      <origin xyz="0.1213 0 0"/>
    </inertial>
  </link>
  <!-- Lower leg link -->
  <link name="rm_lowerleg">
    <visual>
      <geometry>
        <mesh filename="package://mcorin_description/meshes/Tibia.STL" scale="1 1 1"/>
      </geometry>
      <origin rpy="1.57079632679 0 0" xyz="0 0 0"/>
      <material name="yellow"/>
    </visual>
    <collision>
      <geometry>
        <box size="0.12 0.025 0.04"/>
      </geometry>
      <origin rpy="0 0 0" xyz="0.085 0 0"/>
      <material name="colli"/>
    </collision>
    <inertial>
      <mass value="0.0537"/>
      <inertia ixx="1.6e-05" ixy="0" ixz="0" iyy="0.000119" iyz="0" izz="0.00013"/>
      <origin xyz="0.0958 0 0"/>
    </inertial>
  </link>
  <!-- Foot link -->
  <link name="rm_foot">
    <visual>
      <geometry>
        <sphere radius="0.008"/>
      </geometry>
      <origin rpy="0 0 0" xyz="0 0 0"/>
      <material name="blue"/>
    </visual>
    <collision>
      <geometry>
        <sphere radius="0.008"/>
      </geometry>
      <origin rpy="0 0 0" xyz="0 0 0"/>
      <material name="colli"/>
    </collision>
    <inertial>
      <mass value="0.005"/>
      <inertia ixx="5e-05" ixy="0" ixz="0" iyy="5e-05" iyz="0" izz="5e-05"/>
      <origin xyz="0 0 0"/>
    </inertial>
  </link>
  <!-- Hip assembly -->
  <transmission name="rm_q1_trans">
    <type>transmission_interface/SimpleTransmission</type>
    <joint name="rm_q1_joint">
      <hardwareInterface>EffortJointInterface</hardwareInterface>
    </joint>
    <actuator name="rm_q1_motor">
      <hardwareInterface>EffortJointInterface</hardwareInterface>
      <mechanicalReduction>200</mechanicalReduction>
    </actuator>
  </transmission>
  <!-- Upper leg -->
  <transmission name="rm_q2_trans">
    <type>transmission_interface/SimpleTransmission</type>
    <joint name="rm_q2_joint">
      <hardwareInterface>EffortJointInterface</hardwareInterface>
    </joint>
    <actuator name="rm_q2_motor">
      <hardwareInterface>EffortJointInterface</hardwareInterface>
      <mechanicalReduction>200</mechanicalReduction>
    </actuator>
  </transmission>
  <!-- Lower leg -->
  <transmission name="rm_q3_trans">
    <type>transmission_interface/SimpleTransmission</type>
    <joint name="rm_q3_joint">
      <hardwareInterface>EffortJointInterface</hardwareInterface>
    </joint>
    <actuator name="rm_q3_motor">
      <hardwareInterface>EffortJointInterface</hardwareInterface>
      <mechanicalReduction>200</mechanicalReduction>
    </actuator>
  </transmission>
  <gazebo reference="rm_q1_joint">
    <provideFeedback>true</provideFeedback>
  </gazebo>
  <gazebo reference="rm_q2_joint">
    <provideFeedback>true</provideFeedback>
  </gazebo>
  <gazebo reference="rm_q3_joint">
    <provideFeedback>true</provideFeedback>
  </gazebo>
  <gazebo reference="rm_hipassembly">
    <kp>1000000.0</kp>
    <kd>100.0</kd>
    <mu1>1.5</mu1>
    <mu2>1.5</mu2>
    <!-- <fdir1>1 0 0</fdir1> -->
    <maxVel>0.001</maxVel>
    <minDepth>0.00</minDepth>
    <material>Gazebo/White</material>
  </gazebo>
  <gazebo reference="rm_upperleg">
    <kp>1000000.0</kp>
    <kd>100.0</kd>
    <mu1>1.5</mu1>
    <mu2>1.5</mu2>
    <!-- <fdir1>1 0 0</fdir1> -->
    <maxVel>0.001</maxVel>
    <minDepth>0.00</minDepth>
    <material>Gazebo/DarkGrey</material>
  </gazebo>
  <gazebo reference="rm_lowerleg">
    <kp>1000000.0</kp>
    <kd>100.0</kd>
    <mu1>1.5</mu1>
    <mu2>1.5</mu2>
    <!-- <fdir1>1 0 0</fdir1> -->
    <maxVel>0.001</maxVel>
    <minDepth>0.00</minDepth>
    <material>Gazebo/White</material>
  </gazebo>
  <gazebo reference="rm_foot">
    <kp>1000000.0</kp>
    <kd>100.0</kd>
    <mu1>1.5</mu1>
    <mu2>1.5</mu2>
    <!-- <fdir1>1 0 0</fdir1> -->
    <maxVel>0.001</maxVel>
    <minDepth>0.00</minDepth>
    <material>Gazebo/Black</material>
  </gazebo>
  <gazebo reference="rm_foot">
    <!-- contact sensor -->
    <sensor name="foot_contact" type="contact">
      <update_rate>100.0</update_rate>
      <always_on>1</always_on>
      <contact>
        <collision>rm_lowerleg_fixed_joint_lump__rm_foot_collision_1</collision>
        <topic>/rm_foot_contact</topic>
      </contact>
      <plugin filename="libgazebo_ros_bumper.so" name="fixed_jaw_bumper">
        <bumperTopicName>/corin/foot_wrench/rm</bumperTopicName>
        <frameName>rm_foot</frameName>
      </plugin>
    </sensor>
  </gazebo>
  <!-- Joints -->
  <!-- Coxa joint -->
  <joint name="rr_q1_joint" type="revolute">
    <origin rpy="0 0 -1.57079632679" xyz="-0.175 -0.075 0"/>
    <parent link="trunk"/>
    <child link="rr_hipassembly"/>
    <axis xyz="0 0 1"/>
    <limit effort="2.85" lower="-1.6" upper="1.6" velocity="5.23"/>
    <dynamics damping="0.15" friction="0"/>
    <!-- <safety_controller k_position="100" k_velocity="100"
							   soft_lower_limit="${-7*PI/18}" soft_upper_limit="${5*PI/36}" /> -->
  </joint>
  <!-- Upper leg joint -->
  <joint name="rr_q2_joint" type="revolute">
    <origin rpy="1.57079632679 0 0" xyz="0.077 0 0"/>
    <parent link="rr_hipassembly"/>
    <child link="rr_upperleg"/>
    <axis xyz="0 0 1"/>
    <limit effort="2.85" lower="-2.36" upper="2.36" velocity="5.23"/>
    <dynamics damping="0.15" friction="0"/>
    <!-- <safety_controller k_position="100" k_velocity="100"
							   soft_lower_limit="${-(1+reflect_front)*5*PI/36-(1-reflect_front)*7*PI/36}"
							   soft_upper_limit="${(1-reflect_front)*5*PI/36+(1+reflect_front)*7*PI/36}" /> -->
  </joint>
  <!-- Lower leg joint -->
  <joint name="rr_q3_joint" type="revolute">
    <origin rpy="0 0 0" xyz="0.15 0 0"/>
    <parent link="rr_upperleg"/>
    <child link="rr_lowerleg"/>
    <axis xyz="0 0 1"/>
    <limit effort="2.85" lower="-3.1" upper="3.1" velocity="5.23"/>
    <dynamics damping="0.15" friction="0"/>
    <!-- <safety_controller k_position="100" k_velocity="100"
							   soft_lower_limit="${-(1+reflect_front)*7*PI/18+(1-reflect_front)*PI/18}"
							   soft_upper_limit="${(1-reflect_front)*7*PI/18-(1+reflect_front)*PI/18}" /> -->
  </joint>
  <!-- Foot joint -->
  <joint name="rr_foot_joint" type="fixed">
    <origin rpy="0 0 0" xyz="0.16 0 0"/>
    <parent link="rr_lowerleg"/>
    <child link="rr_foot"/>
  </joint>
  <!-- Links -->
  <!-- Hip assembly link -->
  <link name="rr_hipassembly">
    <visual>
      <origin rpy="0 0 0" xyz="0 0 0"/>
      <geometry>
        <mesh filename="package://mcorin_description/meshes/Coxa.STL" scale="1 1 1"/>
      </geometry>
      <material name="green"/>
    </visual>
    <collision>
      <origin rpy="0 0 0" xyz="0.05945 0 0"/>
      <geometry>
        <box size="0.0611 0.046 0.0528"/>
      </geometry>
      <material name="orange"/>
    </collision>
    <inertial>
      <origin xyz="0.058 0 0"/>
      <mass value="0.175"/>
      <inertia ixx="3.2e-05" ixy="0.0" ixz="0.0" iyy="5.6e-05" iyz="0.0" izz="4e-05"/>
    </inertial>
  </link>
  <!-- Upper leg link -->
  <link name="rr_upperleg">
    <visual>
      <geometry>
        <mesh filename="package://mcorin_description/meshes/Femur.STL" scale="1 1 1"/>
      </geometry>
      <origin rpy="1.57079632679 0 0" xyz="0 0 0"/>
      <material name="blue"/>
    </visual>
    <collision>
      <geometry>
        <box size="0.12 0.04 0.04"/>
      </geometry>
      <origin rpy="0 0 0" xyz="0.1 0 0"/>
      <material name="colli"/>
    </collision>
    <inertial>
      <mass value="0.1554"/>
      <inertia ixx="1.9e-05" ixy="0" ixz="0" iyy="6.8e-05" iyz="0" izz="7.9e-05"/>
      <origin xyz="0.1213 0 0"/>
    </inertial>
  </link>
  <!-- Lower leg link -->
  <link name="rr_lowerleg">
    <visual>
      <geometry>
        <mesh filename="package://mcorin_description/meshes/Tibia.STL" scale="1 1 1"/>
      </geometry>
      <origin rpy="1.57079632679 0 0" xyz="0 0 0"/>
      <material name="yellow"/>
    </visual>
    <collision>
      <geometry>
        <box size="0.12 0.025 0.04"/>
      </geometry>
      <origin rpy="0 0 0" xyz="0.085 0 0"/>
      <material name="colli"/>
    </collision>
    <inertial>
      <mass value="0.0537"/>
      <inertia ixx="1.6e-05" ixy="0" ixz="0" iyy="0.000119" iyz="0" izz="0.00013"/>
      <origin xyz="0.0958 0 0"/>
    </inertial>
  </link>
  <!-- Foot link -->
  <link name="rr_foot">
    <visual>
      <geometry>
        <sphere radius="0.008"/>
      </geometry>
      <origin rpy="0 0 0" xyz="0 0 0"/>
      <material name="blue"/>
    </visual>
    <collision>
      <geometry>
        <sphere radius="0.008"/>
      </geometry>
      <origin rpy="0 0 0" xyz="0 0 0"/>
      <material name="colli"/>
    </collision>
    <inertial>
      <mass value="0.005"/>
      <inertia ixx="5e-05" ixy="0" ixz="0" iyy="5e-05" iyz="0" izz="5e-05"/>
      <origin xyz="0 0 0"/>
    </inertial>
  </link>
  <!-- Hip assembly -->
  <transmission name="rr_q1_trans">
    <type>transmission_interface/SimpleTransmission</type>
    <joint name="rr_q1_joint">
      <hardwareInterface>EffortJointInterface</hardwareInterface>
    </joint>
    <actuator name="rr_q1_motor">
      <hardwareInterface>EffortJointInterface</hardwareInterface>
      <mechanicalReduction>200</mechanicalReduction>
    </actuator>
  </transmission>
  <!-- Upper leg -->
  <transmission name="rr_q2_trans">
    <type>transmission_interface/SimpleTransmission</type>
    <joint name="rr_q2_joint">
      <hardwareInterface>EffortJointInterface</hardwareInterface>
    </joint>
    <actuator name="rr_q2_motor">
      <hardwareInterface>EffortJointInterface</hardwareInterface>
      <mechanicalReduction>200</mechanicalReduction>
    </actuator>
  </transmission>
  <!-- Lower leg -->
  <transmission name="rr_q3_trans">
    <type>transmission_interface/SimpleTransmission</type>
    <joint name="rr_q3_joint">
      <hardwareInterface>EffortJointInterface</hardwareInterface>
    </joint>
    <actuator name="rr_q3_motor">
      <hardwareInterface>EffortJointInterface</hardwareInterface>
      <mechanicalReduction>200</mechanicalReduction>
    </actuator>
  </transmission>
  <gazebo reference="rr_q1_joint">
    <provideFeedback>true</provideFeedback>
  </gazebo>
  <gazebo reference="rr_q2_joint">
    <provideFeedback>true</provideFeedback>
  </gazebo>
  <gazebo reference="rr_q3_joint">
    <provideFeedback>true</provideFeedback>
  </gazebo>
  <gazebo reference="rr_hipassembly">
    <kp>1000000.0</kp>
    <kd>100.0</kd>
    <mu1>1.5</mu1>
    <mu2>1.5</mu2>
    <!-- <fdir1>1 0 0</fdir1> -->
    <maxVel>0.001</maxVel>
    <minDepth>0.00</minDepth>
    <material>Gazebo/White</material>
  </gazebo>
  <gazebo reference="rr_upperleg">
    <kp>1000000.0</kp>
    <kd>100.0</kd>
    <mu1>1.5</mu1>
    <mu2>1.5</mu2>
    <!-- <fdir1>1 0 0</fdir1> -->
    <maxVel>0.001</maxVel>
    <minDepth>0.00</minDepth>
    <material>Gazebo/DarkGrey</material>
  </gazebo>
  <gazebo reference="rr_lowerleg">
    <kp>1000000.0</kp>
    <kd>100.0</kd>
    <mu1>1.5</mu1>
    <mu2>1.5</mu2>
    <!-- <fdir1>1 0 0</fdir1> -->
    <maxVel>0.001</maxVel>
    <minDepth>0.00</minDepth>
    <material>Gazebo/White</material>
  </gazebo>
  <gazebo reference="rr_foot">
    <kp>1000000.0</kp>
    <kd>100.0</kd>
    <mu1>1.5</mu1>
    <mu2>1.5</mu2>
    <!-- <fdir1>1 0 0</fdir1> -->
    <maxVel>0.001</maxVel>
    <minDepth>0.00</minDepth>
    <material>Gazebo/Black</material>
  </gazebo>
  <gazebo reference="rr_foot">
    <!-- contact sensor -->
    <sensor name="foot_contact" type="contact">
      <update_rate>100.0</update_rate>
      <always_on>1</always_on>
      <contact>
        <collision>rr_lowerleg_fixed_joint_lump__rr_foot_collision_1</collision>
        <topic>/rr_foot_contact</topic>
      </contact>
      <plugin filename="libgazebo_ros_bumper.so" name="fixed_jaw_bumper">
        <bumperTopicName>/corin/foot_wrench/rr</bumperTopicName>
        <frameName>rr_foot</frameName>
      </plugin>
    </sensor>
  </gazebo>
  <!-- Joint -->
  <joint name="trunk_imu_joint" type="fixed">
    <origin rpy="0 0 0" xyz="0.0 0.0 0.0"/>
    <parent link="trunk"/>
    <child link="trunk_imu"/>
  </joint>
  <!-- Link -->
  <link name="trunk_imu">
    <inertial>
      <origin xyz="-0.00020  0.00010  0.00110"/>
      <mass value="0.010"/>
      <inertia ixx="0.0" ixy="0.0" ixz="0.0" iyy="0.0" iyz="0.0" izz="0.0"/>
    </inertial>
    <visual>
      <origin rpy="0 0 0" xyz="0.0 0 0.0"/>
      <geometry>
        <box size="0.05 0.05 0.01"/>
      </geometry>
      <material name="black">
        <color rgba="0 0 0 0.9"/>
      </material>
    </visual>
  </link>
  <gazebo>
    <material>Gazebo/Red</material>
    <plugin filename="libgazebo_ros_imu.so" name="imu_plugin">
      <robotNamespace>/corin/imu/</robotNamespace>
      <alwaysOn>true</alwaysOn>
      <frameName>trunk_imu</frameName>
      <bodyName>trunk_imu</bodyName>
      <topicName>trunk/data</topicName>
      <serviceName>trunk/service</serviceName>
      <gaussianNoise>0.001</gaussianNoise>
      <updateRate>100</updateRate>
    </plugin>
  </gazebo>
  <!-- Joint -->
  <joint name="trunk_lidar_joint" type="fixed">
    <origin rpy="0 0 1.57079632679" xyz="0.06 0.0 0.03"/>
    <parent link="trunk"/>
    <child link="trunk_lidar"/>
  </joint>
  <!-- Link -->
  <link name="trunk_lidar">
    <inertial>
      <origin xyz="-0.00020  0.00010  0.00110"/>
      <mass value="0.010"/>
      <inertia ixx="0.0" ixy="0.0" ixz="0.0" iyy="0.0" iyz="0.0" izz="0.0"/>
    </inertial>
    <visual>
      <origin rpy="0 0 0" xyz="0.0 0 0.0"/>
      <geometry>
        <cylinder length="0.01" radius="0.01"/>
      </geometry>
      <material name="black">
        <color rgba="0 0 0 0.9"/>
      </material>
    </visual>
  </link>
  <gazebo reference="trunk_lidar">
    <material>Gazebo/Blue</material>
    <sensor name="head_hokuyo_sensor" type="ray">
      <pose>0 0 0 0 0 0</pose>
      <visualize>true</visualize>
      <update_rate>100</update_rate>
      <ray>
        <scan>
          <horizontal>
            <samples>5</samples>
            <resolution>1</resolution>
            <min_angle>-0.009</min_angle>
            <max_angle>0.009</max_angle>
          </horizontal>
        </scan>
        <range>
          <min>0.01</min>
          <max>1.0</max>
          <resolution>0.005</resolution>
        </range>
        <noise>
          <type>none</type>
          <mean>0.0</mean>
          <stddev>0.0</stddev>
        </noise>
      </ray>
      <plugin filename="libgazebo_ros_laser.so" name="gazebo_ros_head_hokuyo_controller">
        <robotNamespace>/corin/lidar/</robotNamespace>
        <alwaysOn>true</alwaysOn>
        <update_rate>100</update_rate>
        <topicName>lidar/data</topicName>
        <frameName>trunk</frameName>
        <bodyName>trunk</bodyName>
      </plugin>
    </sensor>
  </gazebo>
</robot>

